Workbook

Sheet Dashboard
A1: 📊 RETURNS MANAGEMENT DASHBOARD — Full Year (W1–W52)
A2: ⚡ Just paste data in the 'Raw Data' sheet — this dashboard auto-updates. Each week column fills as you add data. Press Ctrl+Alt+F9 to force refresh.
A3: Particulars | B3: W1 | E3: W2 | H3: W3 | K3: W4 | N3: W5 | Q3: W6 | T3: W7 | W3: W8 | Z3: W9 | AC3: W10 | AF3: W11 | AI3: W12 | AL3: W13 | AO3: W14 | AR3: W15 | AU3: W16 | AX3: W17 | BA3: W18 | BD3: W19 | BG3: W20 | BJ3: W21 | BM3: W22 | BP3: W23 | BS3: W24 | BV3: W25 | BY3: W26 | CB3: W27 | CE3: W28 | CH3: W29 | CK3: W30 | CN3: W31 | CQ3: W32 | CT3: W33 | CW3: W34 | CZ3: W35 | DC3: W36 | DF3: W37 | DI3: W38 | DL3: W39 | DO3: W40 | DR3: W41 | DU3: W42 | DX3: W43 | EA3: W44 | ED3: W45 | EG3: W46 | EJ3: W47 | EM3: W48 | EP3: W49 | ES3: W50 | EV3: W51 | EY3: W52 | FB3: TOTAL (All Weeks)
B4: COGS (£) | C4: Sales (£) | D4: Units | E4: COGS (£) | F4: Sales (£) | G4: Units | H4: COGS (£) | I4: Sales (£) | J4: Units | K4: COGS (£) | L4: Sales (£) | M4: Units | N4: COGS (£) | O4: Sales (£) | P4: Units | Q4: COGS (£) | R4: Sales (£) | S4: Units | T4: COGS (£) | U4: Sales (£) | V4: Units | W4: COGS (£) | X4: Sales (£) | Y4: Units | Z4: COGS (£) | AA4: Sales (£) | AB4: Units | AC4: COGS (£) | AD4: Sales (£) | AE4: Units | AF4: COGS (£) | AG4: Sales (£) | AH4: Units | AI4: COGS (£) | AJ4: Sales (£) | AK4: Units | AL4: COGS (£) | AM4: Sales (£) | AN4: Units | AO4: COGS (£) | AP4: Sales (£) | AQ4: Units | AR4: COGS (£) | AS4: Sales (£) | AT4: Units | AU4: COGS (£) | AV4: Sales (£) | AW4: Units | AX4: COGS (£) | AY4: Sales (£) | AZ4: Units | BA4: COGS (£) | BB4: Sales (£) | BC4: Units | BD4: COGS (£) | BE4: Sales (£) | BF4: Units | BG4: COGS (£) | BH4: Sales (£) | BI4: Units | BJ4: COGS (£) | BK4: Sales (£) | BL4: Units | BM4: COGS (£) | BN4: Sales (£) | BO4: Units | BP4: COGS (£) | BQ4: Sales (£) | BR4: Units | BS4: COGS (£) | BT4: Sales (£) | BU4: Units | BV4: COGS (£) | BW4: Sales (£) | BX4: Units | BY4: COGS (£) | BZ4: Sales (£) | CA4: Units | CB4: COGS (£) | CC4: Sales (£) | CD4: Units | CE4: COGS (£) | CF4: Sales (£) | CG4: Units | CH4: COGS (£) | CI4: Sales (£) | CJ4: Units | CK4: COGS (£) | CL4: Sales (£) | CM4: Units | CN4: COGS (£) | CO4: Sales (£) | CP4: Units | CQ4: COGS (£) | CR4: Sales (£) | CS4: Units | CT4: COGS (£) | CU4: Sales (£) | CV4: Units | CW4: COGS (£) | CX4: Sales (£) | CY4: Units | CZ4: COGS (£) | DA4: Sales (£) | DB4: Units | DC4: COGS (£) | DD4: Sales (£) | DE4: Units | DF4: COGS (£) | DG4: Sales (£) | DH4: Units | DI4: COGS (£) | DJ4: Sales (£) | DK4: Units | DL4: COGS (£) | DM4: Sales (£) | DN4: Units | DO4: COGS (£) | DP4: Sales (£) | DQ4: Units | DR4: COGS (£) | DS4: Sales (£) | DT4: Units | DU4: COGS (£) | DV4: Sales (£) | DW4: Units | DX4: COGS (£) | DY4: Sales (£) | DZ4: Units | EA4: COGS (£) | EB4: Sales (£) | EC4: Units | ED4: COGS (£) | EE4: Sales (£) | EF4: Units | EG4: COGS (£) | EH4: Sales (£) | EI4: Units | EJ4: COGS (£) | EK4: Sales (£) | EL4: Units | EM4: COGS (£) | EN4: Sales (£) | EO4: Units | EP4: COGS (£) | EQ4: Sales (£) | ER4: Units | ES4: COGS (£) | ET4: Sales (£) | EU4: Units | EV4: COGS (£) | EW4: Sales (£) | EX4: Units | EY4: COGS (£) | EZ4: Sales (£) | FA4: Units | FB4: COGS (£) | FC4: Sales (£) | FD4: Units
A5: Total Returns Value | B5: =SUMIFS('Raw Data'!$M$3:$M$5000,'Raw Data'!$P$3:$P$5000,"W1") -> 0 | C5: =SUMIFS('Raw Data'!$N$3:$N$5000,'Raw Data'!$P$3:$P$5000,"W1") -> 0 | D5: =SUMIFS('Raw Data'!$E$3:$E$5000,'Raw Data'!$P$3:$P$5000,"W1") -> 0 | E5: =SUMIFS('Raw Data'!$M$3:$M$5000,'Raw Data'!$P$3:$P$5000,"W2") -> 0 | F5: =SUMIFS('Raw Data'!$N$3:$N$5000,'Raw Data'!$P$3:$P$5000,"W2") -> 0 | G5: =SUMIFS('Raw Data'!$E$3:$E$5000,'Raw Data'!$P$3:$P$5000,"W2") -> 0 | H5: =SUMIFS('Raw Data'!$M$3:$M$5000,'Raw Data'!$P$3:$P$5000,"W3") -> 0 | I5: =SUMIFS('Raw Data'!$N$3:$N$5000,'Raw Data'!$P$3:$P$5000,"W3") -> 0 | J5: =SUMIFS('Raw Data'!$E$3:$E$5000,'Raw Data'!$P$3:$P$5000,"W3") -> 0 | K5: =SUMIFS('Raw Data'!$M$3:$M$5000,'Raw Data'!$P$3:$P$5000,"W4") -> 0 | L5: =SUMIFS('Raw Data'!$N$3:$N$5000,'Raw Data'!$P$3:$P$5000,"W4") -> 0 | M5: =SUMIFS('Raw Data'!$E$3:$E$5000,'Raw Data'!$P$3:$P$5000,"W4") -> 0 | N5: =SUMIFS('Raw Data'!$M$3:$M$5000,'Raw Data'!$P$3:$P$5000,"W5") -> 0 | O5: =SUMIFS('Raw Data'!$N$3:$N$5000,'Raw Data'!$P$3:$P$5000,"W5") -> 0 | P5: =SUMIFS('Raw Data'!$E$3:$E$5000,'Raw Data'!$P$3:$P$5000,"W5") -> 0 | Q5: =SUMIFS('Raw Data'!$M$3:$M$5000,'Raw Data'!$P$3:$P$5000,"W6") -> 0 | R5: =SUMIFS('Raw Data'!$N$3:$N$5000,'Raw Data'!$P$3:$P$5000,"W6") -> 0 | S5: =SUMIFS('Raw Data'!$E$3:$E$5000,'Raw Data'!$P$3:$P$5000,"W6") -> 0 | T5: =SUMIFS('Raw Data'!$M$3:$M$5000,'Raw Data'!$P$3:$P$5000,"W7") -> 0 | U5: =SUMIFS('Raw Data'!$N$3:$N$5000,'Raw Data'!$P$3:$P$5000,"W7") -> 0 | V5: =SUMIFS('Raw Data'!$E$3:$E$5000,'Raw Data'!$P$3:$P$5000,"W7") -> 0 | W5: =SUMIFS('Raw Data'!$M$3:$M$5000,'Raw Data'!$P$3:$P$5000,"W8") -> 0 | X5: =SUMIFS('Raw Data'!$N$3:$N$5000,'Raw Data'!$P$3:$P$5000,"W8") -> 0 | Y5: =SUMIFS('Raw Data'!$E$3:$E$5000,'Raw Data'!$P$3:$P$5000,"W8") -> 0 | Z5: =SUMIFS('Raw Data'!$M$3:$M$5000,'Raw Data'!$P$3:$P$5000,"W9") -> 1685 | AA5: =SUMIFS('Raw Data'!$N$3:$N$5000,'Raw Data'!$P$3:$P$5000,"W9") -> 3654 | AB5: =SUMIFS('Raw Data'!$E$3:$E$5000,'Raw Data'!$P$3:$P$5000,"W9") -> 20 | AC5: =SUMIFS('Raw Data'!$M$3:$M$5000,'Raw Data'!$P$3:$P$5000,"W10") -> 1148.42 | AD5: =SUMIFS('Raw Data'!$N$3:$N$5000,'Raw Data'!$P$3:$P$5000,"W10") -> 2586.92 | AE5: =SUMIFS('Raw Data'!$E$3:$E$5000,'Raw Data'!$P$3:$P$5000,"W10") -> 15 | AF5: =SUMIFS('Raw Data'!$M$3:$M$5000,'Raw Data'!$P$3:$P$5000,"W11") -> 4595 | AG5: =SUMIFS('Raw Data'!$N$3:$N$5000,'Raw Data'!$P$3:$P$5000,"W11") -> 9915 | AH5: =SUMIFS('Raw Data'!$E$3:$E$5000,'Raw Data'!$P$3:$P$5000,"W11") -> 104 | AI5: =SUMIFS('Raw Data'!$M$3:$M$5000,'Raw Data'!$P$3:$P$5000,"W12") -> 0 | AJ5: =SUMIFS('Raw Data'!$N$3:$N$5000,'Raw Data'!$P$3:$P$5000,"W12") -> 0 | AK5: =SUMIFS('Raw Data'!$E$3:$E$5000,'Raw Data'!$P$3:$P$5000,"W12") -> 0 | AL5: =SUMIFS('Raw Data'!$M$3:$M$5000,'Raw Data'!$P$3:$P$5000,"W13") -> 0 | AM5: =SUMIFS('Raw Data'!$N$3:$N$5000,'Raw Data'!$P$3:$P$5000,"W13") -> 0 | AN5: =SUMIFS('Raw Data'!$E$3:$E$5000,'Raw Data'!$P$3:$P$5000,"W13") -> 0 | AO5: =SUMIFS('Raw Data'!$M$3:$M$5000,'Raw Data'!$P$3:$P$5000,"W14") -> 0 | AP5: =SUMIFS('Raw Data'!$N$3:$N$5000,'Raw Data'!$P$3:$P$5000,"W14") -> 0 | AQ5: =SUMIFS('Raw Data'!$E$3:$E$5000,'Raw Data'!$P$3:$P$5000,"W14") -> 0 | AR5: =SUMIFS('Raw Data'!$M$3:$M$5000,'Raw Data'!$P$3:$P$5000,"W15") -> 0 | AS5: =SUMIFS('Raw Data'!$N$3:$N$5000,'Raw Data'!$P$3:$P$5000,"W15") -> 0 | AT5: =SUMIFS('Raw Data'!$E$3:$E$5000,'Raw Data'!$P$3:$P$5000,"W15") -> 0 | AU5: =SUMIFS('Raw Data'!$M$3:$M$5000,'Raw Data'!$P$3:$P$5000,"W16") -> 0 | AV5: =SUMIFS('Raw Data'!$N$3:$N$5000,'Raw Data'!$P$3:$P$5000,"W16") -> 0 | AW5: =SUMIFS('Raw Data'!$E$3:$E$5000,'Raw Data'!$P$3:$P$5000,"W16") -> 0 | AX5: =SUMIFS('Raw Data'!$M$3:$M$5000,'Raw Data'!$P$3:$P$5000,"W17") -> 0 | AY5: =SUMIFS('Raw Data'!$N$3:$N$5000,'Raw Data'!$P$3:$P$5000,"W17") -> 0 | AZ5: =SUMIFS('Raw Data'!$E$3:$E$5000,'Raw Data'!$P$3:$P$5000,"W17") -> 0 | BA5: =SUMIFS('Raw Data'!$M$3:$M$5000,'Raw Data'!$P$3:$P$5000,"W18") -> 0 | BB5: =SUMIFS('Raw Data'!$N$3:$N$5000,'Raw Data'!$P$3:$P$5000,"W18") -> 0 | BC5: =SUMIFS('Raw Data'!$E$3:$E$5000,'Raw Data'!$P$3:$P$5000,"W18") -> 0 | BD5: =SUMIFS('Raw Data'!$M$3:$M$5000,'Raw Data'!$P$3:$P$5000,"W19") -> 0 | BE5: =SUMIFS('Raw Data'!$N$3:$N$5000,'Raw Data'!$P$3:$P$5000,"W19") -> 0 | BF5: =SUMIFS('Raw Data'!$E$3:$E$5000,'Raw Data'!$P$3:$P$5000,"W19") -> 0 | BG5: =SUMIFS('Raw Data'!$M$3:$M$5000,'Raw Data'!$P$3:$P$5000,"W20") -> 0 | BH5: =SUMIFS('Raw Data'!$N$3:$N$5000,'Raw Data'!$P$3:$P$5000,"W20") -> 0 | BI5: =SUMIFS('Raw Data'!$E$3:$E$5000,'Raw Data'!$P$3:$P$5000,"W20") -> 0 | BJ5: =SUMIFS('Raw Data'!$M$3:$M$5000,'Raw Data'!$P$3:$P$5000,"W21") -> 0 | BK5: =SUMIFS('Raw Data'!$N$3:$N$5000,'Raw Data'!$P$3:$P$5000,"W21") -> 0 | BL5: =SUMIFS('Raw Data'!$E$3:$E$5000,'Raw Data'!$P$3:$P$5000,"W21") -> 0 | BM5: =SUMIFS('Raw Data'!$M$3:$M$5000,'Raw Data'!$P$3:$P$5000,"W22") -> 0 | BN5: =SUMIFS('Raw Data'!$N$3:$N$5000,'Raw Data'!$P$3:$P$5000,"W22") -> 0 | BO5: =SUMIFS('Raw Data'!$E$3:$E$5000,'Raw Data'!$P$3:$P$5000,"W22") -> 0 | BP5: =SUMIFS('Raw Data'!$M$3:$M$5000,'Raw Data'!$P$3:$P$5000,"W23") -> 0 | BQ5: =SUMIFS('Raw Data'!$N$3:$N$5000,'Raw Data'!$P$3:$P$5000,"W23") -> 0 | BR5: =SUMIFS('Raw Data'!$E$3:$E$5000,'Raw Data'!$P$3:$P$5000,"W23") -> 0 | BS5: =SUMIFS('Raw Data'!$M$3:$M$5000,'Raw Data'!$P$3:$P$5000,"W24") -> 0 | BT5: =SUMIFS('Raw Data'!$N$3:$N$5000,'Raw Data'!$P$3:$P$5000,"W24") -> 0 | BU5: =SUMIFS('Raw Data'!$E$3:$E$5000,'Raw Data'!$P$3:$P$5000,"W24") -> 0 | BV5: =SUMIFS('Raw Data'!$M$3:$M$5000,'Raw Data'!$P$3:$P$5000,"W25") -> 0 | BW5: =SUMIFS('Raw Data'!$N$3:$N$5000,'Raw Data'!$P$3:$P$5000,"W25") -> 0 | BX5: =SUMIFS('Raw Data'!$E$3:$E$5000,'Raw Data'!$P$3:$P$5000,"W25") -> 0 | BY5: =SUMIFS('Raw Data'!$M$3:$M$5000,'Raw Data'!$P$3:$P$5000,"W26") -> 0 | BZ5: =SUMIFS('Raw Data'!$N$3:$N$5000,'Raw Data'!$P$3:$P$5000,"W26") -> 0 | CA5: =SUMIFS('Raw Data'!$E$3:$E$5000,'Raw Data'!$P$3:$P$5000,"W26") -> 0 | CB5: =SUMIFS('Raw Data'!$M$3:$M$5000,'Raw Data'!$P$3:$P$5000,"W27") -> 0 | CC5: =SUMIFS('Raw Data'!$N$3:$N$5000,'Raw Data'!$P$3:$P$5000,"W27") -> 0 | CD5: =SUMIFS('Raw Data'!$E$3:$E$5000,'Raw Data'!$P$3:$P$5000,"W27") -> 0 | CE5: =SUMIFS('Raw Data'!$M$3:$M$5000,'Raw Data'!$P$3:$P$5000,"W28") -> 0 | CF5: =SUMIFS('Raw Data'!$N$3:$N$5000,'Raw Data'!$P$3:$P$5000,"W28") -> 0 | CG5: =SUMIFS('Raw Data'!$E$3:$E$5000,'Raw Data'!$P$3:$P$5000,"W28") -> 0 | CH5: =SUMIFS('Raw Data'!$M$3:$M$5000,'Raw Data'!$P$3:$P$5000,"W29") -> 0 | CI5: =SUMIFS('Raw Data'!$N$3:$N$5000,'Raw Data'!$P$3:$P$5000,"W29") -> 0 | CJ5: =SUMIFS('Raw Data'!$E$3:$E$5000,'Raw Data'!$P$3:$P$5000,"W29") -> 0 | CK5: =SUMIFS('Raw Data'!$M$3:$M$5000,'Raw Data'!$P$3:$P$5000,"W30") -> 0 | CL5: =SUMIFS('Raw Data'!$N$3:$N$5000,'Raw Data'!$P$3:$P$5000,"W30") -> 0 | CM5: =SUMIFS('Raw Data'!$E$3:$E$5000,'Raw Data'!$P$3:$P$5000,"W30") -> 0 | CN5: =SUMIFS('Raw Data'!$M$3:$M$5000,'Raw Data'!$P$3:$P$5000,"W31") -> 0 | CO5: =SUMIFS('Raw Data'!$N$3:$N$5000,'Raw Data'!$P$3:$P$5000,"W31") -> 0 | CP5: =SUMIFS('Raw Data'!$E$3:$E$5000,'Raw Data'!$P$3:$P$5000,"W31") -> 0 | CQ5: =SUMIFS('Raw Data'!$M$3:$M$5000,'Raw Data'!$P$3:$P$5000,"W32") -> 0 | CR5: =SUMIFS('Raw Data'!$N$3:$N$5000,'Raw Data'!$P$3:$P$5000,"W32") -> 0 | CS5: =SUMIFS('Raw Data'!$E$3:$E$5000,'Raw Data'!$P$3:$P$5000,"W32") -> 0 | CT5: =SUMIFS('Raw Data'!$M$3:$M$5000,'Raw Data'!$P$3:$P$5000,"W33") -> 0 | CU5: =SUMIFS('Raw Data'!$N$3:$N$5000,'Raw Data'!$P$3:$P$5000,"W33") -> 0 | CV5: =SUMIFS('Raw Data'!$E$3:$E$5000,'Raw Data'!$P$3:$P$5000,"W33") -> 0 | CW5: =SUMIFS('Raw Data'!$M$3:$M$5000,'Raw Data'!$P$3:$P$5000,"W34") -> 0 | CX5: =SUMIFS('Raw Data'!$N$3:$N$5000,'Raw Data'!$P$3:$P$5000,"W34") -> 0 | CY5: =SUMIFS('Raw Data'!$E$3:$E$5000,'Raw Data'!$P$3:$P$5000,"W34") -> 0 | CZ5: =SUMIFS('Raw Data'!$M$3:$M$5000,'Raw Data'!$P$3:$P$5000,"W35") -> 0 | DA5: =SUMIFS('Raw Data'!$N$3:$N$5000,'Raw Data'!$P$3:$P$5000,"W35") -> 0 | DB5: =SUMIFS('Raw Data'!$E$3:$E$5000,'Raw Data'!$P$3:$P$5000,"W35") -> 0 | DC5: =SUMIFS('Raw Data'!$M$3:$M$5000,'Raw Data'!$P$3:$P$5000,"W36") -> 0 | DD5: =SUMIFS('Raw Data'!$N$3:$N$5000,'Raw Data'!$P$3:$P$5000,"W36") -> 0 | DE5: =SUMIFS('Raw Data'!$E$3:$E$5000,'Raw Data'!$P$3:$P$5000,"W36") -> 0 | DF5: =SUMIFS('Raw Data'!$M$3:$M$5000,'Raw Data'!$P$3:$P$5000,"W37") -> 0 | DG5: =SUMIFS('Raw Data'!$N$3:$N$5000,'Raw Data'!$P$3:$P$5000,"W37") -> 0 | DH5: =SUMIFS('Raw Data'!$E$3:$E$5000,'Raw Data'!$P$3:$P$5000,"W37") -> 0 | DI5: =SUMIFS('Raw Data'!$M$3:$M$5000,'Raw Data'!$P$3:$P$5000,"W38") -> 0 | DJ5: =SUMIFS('Raw Data'!$N$3:$N$5000,'Raw Data'!$P$3:$P$5000,"W38") -> 0 | DK5: =SUMIFS('Raw Data'!$E$3:$E$5000,'Raw Data'!$P$3:$P$5000,"W38") -> 0 | DL5: =SUMIFS('Raw Data'!$M$3:$M$5000,'Raw Data'!$P$3:$P$5000,"W39") -> 0 | DM5: =SUMIFS('Raw Data'!$N$3:$N$5000,'Raw Data'!$P$3:$P$5000,"W39") -> 0 | DN5: =SUMIFS('Raw Data'!$E$3:$E$5000,'Raw Data'!$P$3:$P$5000,"W39") -> 0 | DO5: =SUMIFS('Raw Data'!$M$3:$M$5000,'Raw Data'!$P$3:$P$5000,"W40") -> 0 | DP5: =SUMIFS('Raw Data'!$N$3:$N$5000,'Raw Data'!$P$3:$P$5000,"W40") -> 0 | DQ5: =SUMIFS('Raw Data'!$E$3:$E$5000,'Raw Data'!$P$3:$P$5000,"W40") -> 0 | DR5: =SUMIFS('Raw Data'!$M$3:$M$5000,'Raw Data'!$P$3:$P$5000,"W41") -> 0 | DS5: =SUMIFS('Raw Data'!$N$3:$N$5000,'Raw Data'!$P$3:$P$5000,"W41") -> 0 | DT5: =SUMIFS('Raw Data'!$E$3:$E$5000,'Raw Data'!$P$3:$P$5000,"W41") -> 0 | DU5: =SUMIFS('Raw Data'!$M$3:$M$5000,'Raw Data'!$P$3:$P$5000,"W42") -> 0 | DV5: =SUMIFS('Raw Data'!$N$3:$N$5000,'Raw Data'!$P$3:$P$5000,"W42") -> 0 | DW5: =SUMIFS('Raw Data'!$E$3:$E$5000,'Raw Data'!$P$3:$P$5000,"W42") -> 0 | DX5: =SUMIFS('Raw Data'!$M$3:$M$5000,'Raw Data'!$P$3:$P$5000,"W43") -> 0 | DY5: =SUMIFS('Raw Data'!$N$3:$N$5000,'Raw Data'!$P$3:$P$5000,"W43") -> 0 | DZ5: =SUMIFS('Raw Data'!$E$3:$E$5000,'Raw Data'!$P$3:$P$5000,"W43") -> 0 | EA5: =SUMIFS('Raw Data'!$M$3:$M$5000,'Raw Data'!$P$3:$P$5000,"W44") -> 0 | EB5: =SUMIFS('Raw Data'!$N$3:$N$5000,'Raw Data'!$P$3:$P$5000,"W44") -> 0 | EC5: =SUMIFS('Raw Data'!$E$3:$E$5000,'Raw Data'!$P$3:$P$5000,"W44") -> 0 | ED5: =SUMIFS('Raw Data'!$M$3:$M$5000,'Raw Data'!$P$3:$P$5000,"W45") -> 0 | EE5: =SUMIFS('Raw Data'!$N$3:$N$5000,'Raw Data'!$P$3:$P$5000,"W45") -> 0 | EF5: =SUMIFS('Raw Data'!$E$3:$E$5000,'Raw Data'!$P$3:$P$5000,"W45") -> 0 | EG5: =SUMIFS('Raw Data'!$M$3:$M$5000,'Raw Data'!$P$3:$P$5000,"W46") -> 0 | EH5: =SUMIFS('Raw Data'!$N$3:$N$5000,'Raw Data'!$P$3:$P$5000,"W46") -> 0 | EI5: =SUMIFS('Raw Data'!$E$3:$E$5000,'Raw Data'!$P$3:$P$5000,"W46") -> 0 | EJ5: =SUMIFS('Raw Data'!$M$3:$M$5000,'Raw Data'!$P$3:$P$5000,"W47") -> 0 | EK5: =SUMIFS('Raw Data'!$N$3:$N$5000,'Raw Data'!$P$3:$P$5000,"W47") -> 0 | EL5: =SUMIFS('Raw Data'!$E$3:$E$5000,'Raw Data'!$P$3:$P$5000,"W47") -> 0 | EM5: =SUMIFS('Raw Data'!$M$3:$M$5000,'Raw Data'!$P$3:$P$5000,"W48") -> 0 | EN5: =SUMIFS('Raw Data'!$N$3:$N$5000,'Raw Data'!$P$3:$P$5000,"W48") -> 0 | EO5: =SUMIFS('Raw Data'!$E$3:$E$5000,'Raw Data'!$P$3:$P$5000,"W48") -> 0 | EP5: =SUMIFS('Raw Data'!$M$3:$M$5000,'Raw Data'!$P$3:$P$5000,"W49") -> 0 | EQ5: =SUMIFS('Raw Data'!$N$3:$N$5000,'Raw Data'!$P$3:$P$5000,"W49") -> 0 | ER5: =SUMIFS('Raw Data'!$E$3:$E$5000,'Raw Data'!$P$3:$P$5000,"W49") -> 0 | ES5: =SUMIFS('Raw Data'!$M$3:$M$5000,'Raw Data'!$P$3:$P$5000,"W50") -> 0 | ET5: =SUMIFS('Raw Data'!$N$3:$N$5000,'Raw Data'!$P$3:$P$5000,"W50") -> 0 | EU5: =SUMIFS('Raw Data'!$E$3:$E$5000,'Raw Data'!$P$3:$P$5000,"W50") -> 0 | EV5: =SUMIFS('Raw Data'!$M$3:$M$5000,'Raw Data'!$P$3:$P$5000,"W51") -> 0 | EW5: =SUMIFS('Raw Data'!$N$3:$N$5000,'Raw Data'!$P$3:$P$5000,"W51") -> 0 | EX5: =SUMIFS('Raw Data'!$E$3:$E$5000,'Raw Data'!$P$3:$P$5000,"W51") -> 0 | EY5: =SUMIFS('Raw Data'!$M$3:$M$5000,'Raw Data'!$P$3:$P$5000,"W52") -> 0 | EZ5: =SUMIFS('Raw Data'!$N$3:$N$5000,'Raw Data'!$P$3:$P$5000,"W52") -> 0 | FA5: =SUMIFS('Raw Data'!$E$3:$E$5000,'Raw Data'!$P$3:$P$5000,"W52") -> 0 | FB5: =B5+E5+H5+K5+N5+Q5+T5+W5+Z5+AC5+AF5+AI5+AL5+AO5+AR5+AU5+AX5+BA5+BD5+BG5+BJ5+BM5+BP5+BS5+BV5+BY5+CB5+CE5+CH5+CK5+CN5+CQ5+CT5+CW5+CZ5+DC5+DF5+DI5+DL5+DO5+DR5+DU5+DX5+EA5+ED5+EG5+EJ5+EM5+EP5+ES5+EV5+EY5 -> 7428.42 | FC5: =C5+F5+I5+L5+O5+R5+U5+X5+AA5+AD5+AG5+AJ5+AM5+AP5+AS5+AV5+AY5+BB5+BE5+BH5+BK5+BN5+BQ5+BT5+BW5+BZ5+CC5+CF5+CI5+CL5+CO5+CR5+CU5+CX5+DA5+DD5+DG5+DJ5+DM5+DP5+DS5+DV5+DY5+EB5+EE5+EH5+EK5+EN5+EQ5+ET5+EW5+EZ5 -> 16155.92 | FD5: =D5+G5+J5+M5+P5+S5+V5+Y5+AB5+AE5+AH5+AK5+AN5+AQ5+AT5+AW5+AZ5+BC5+BF5+BI5+BL5+BO5+BR5+BU5+BX5+CA5+CD5+CG5+CJ5+CM5+CP5+CS5+CV5+CY5+DB5+DE5+DH5+DK5+DN5+DQ5+DT5+DW5+DZ5+EC5+EF5+EI5+EL5+EO5+ER5+EU5+EX5+FA5 -> 139
A6: Green Return | B6: =SUMIFS('Raw Data'!$M$3:$M$5000,'Raw Data'!$P$3:$P$5000,"W1",'Raw Data'!$F$3:$F$5000,"*green return*") -> 0 | C6: =SUMIFS('Raw Data'!$N$3:$N$5000,'Raw Data'!$P$3:$P$5000,"W1",'Raw Data'!$F$3:$F$5000,"*green return*") -> 0 | D6: =SUMIFS('Raw Data'!$E$3:$E$5000,'Raw Data'!$P$3:$P$5000,"W1",'Raw Data'!$F$3:$F$5000,"*green return*") -> 0 | E6: =SUMIFS('Raw Data'!$M$3:$M$5000,'Raw Data'!$P$3:$P$5000,"W2",'Raw Data'!$F$3:$F$5000,"*green return*") -> 0 | F6: =SUMIFS('Raw Data'!$N$3:$N$5000,'Raw Data'!$P$3:$P$5000,"W2",'Raw Data'!$F$3:$F$5000,"*green return*") -> 0 | G6: =SUMIFS('Raw Data'!$E$3:$E$5000,'Raw Data'!$P$3:$P$5000,"W2",'Raw Data'!$F$3:$F$5000,"*green return*") -> 0 | H6: =SUMIFS('Raw Data'!$M$3:$M$5000,'Raw Data'!$P$3:$P$5000,"W3",'Raw Data'!$F$3:$F$5000,"*green return*") -> 0 | I6: =SUMIFS('Raw Data'!$N$3:$N$5000,'Raw Data'!$P$3:$P$5000,"W3",'Raw Data'!$F$3:$F$5000,"*green return*") -> 0 | J6: =SUMIFS('Raw Data'!$E$3:$E$5000,'Raw Data'!$P$3:$P$5000,"W3",'Raw Data'!$F$3:$F$5000,"*green return*") -> 0 | K6: =SUMIFS('Raw Data'!$M$3:$M$5000,'Raw Data'!$P$3:$P$5000,"W4",'Raw Data'!$F$3:$F$5000,"*green return*") -> 0 | L6: =SUMIFS('Raw Data'!$N$3:$N$5000,'Raw Data'!$P$3:$P$5000,"W4",'Raw Data'!$F$3:$F$5000,"*green return*") -> 0 | M6: =SUMIFS('Raw Data'!$E$3:$E$5000,'Raw Data'!$P$3:$P$5000,"W4",'Raw Data'!$F$3:$F$5000,"*green return*") -> 0 | N6: =SUMIFS('Raw Data'!$M$3:$M$5000,'Raw Data'!$P$3:$P$5000,"W5",'Raw Data'!$F$3:$F$5000,"*green return*") -> 0 | O6: =SUMIFS('Raw Data'!$N$3:$N$5000,'Raw Data'!$P$3:$P$5000,"W5",'Raw Data'!$F$3:$F$5000,"*green return*") -> 0 | P6: =SUMIFS('Raw Data'!$E$3:$E$5000,'Raw Data'!$P$3:$P$5000,"W5",'Raw Data'!$F$3:$F$5000,"*green return*") -> 0 | Q6: =SUMIFS('Raw Data'!$M$3:$M$5000,'Raw Data'!$P$3:$P$5000,"W6",'Raw Data'!$F$3:$F$5000,"*green return*") -> 0 | R6: =SUMIFS('Raw Data'!$N$3:$N$5000,'Raw Data'!$P$3:$P$5000,"W6",'Raw Data'!$F$3:$F$5000,"*green return*") -> 0 | S6: =SUMIFS('Raw Data'!$E$3:$E$5000,'Raw Data'!$P$3:$P$5000,"W6",'Raw Data'!$F$3:$F$5000,"*green return*") -> 0 | T6: =SUMIFS('Raw Data'!$M$3:$M$5000,'Raw Data'!$P$3:$P$5000,"W7",'Raw Data'!$F$3:$F$5000,"*green return*") -> 0 | U6: =SUMIFS('Raw Data'!$N$3:$N$5000,'Raw Data'!$P$3:$P$5000,"W7",'Raw Data'!$F$3:$F$5000,"*green return*") -> 0 | V6: =SUMIFS('Raw Data'!$E$3:$E$5000,'Raw Data'!$P$3:$P$5000,"W7",'Raw Data'!$F$3:$F$5000,"*green return*") -> 0 | W6: =SUMIFS('Raw Data'!$M$3:$M$5000,'Raw Data'!$P$3:$P$5000,"W8",'Raw Data'!$F$3:$F$5000,"*green return*") -> 0 | X6: =SUMIFS('Raw Data'!$N$3:$N$5000,'Raw Data'!$P$3:$P$5000,"W8",'Raw Data'!$F$3:$F$5000,"*green return*") -> 0 | Y6: =SUMIFS('Raw Data'!$E$3:$E$5000,'Raw Data'!$P$3:$P$5000,"W8",'Raw Data'!$F$3:$F$5000,"*green return*") -> 0 | Z6: =SUMIFS('Raw Data'!$M$3:$M$5000,'Raw Data'!$P$3:$P$5000,"W9",'Raw Data'!$F$3:$F$5000,"*green return*") -> 0 | AA6: =SUMIFS('Raw Data'!$N$3:$N$5000,'Raw Data'!$P$3:$P$5000,"W9",'Raw Data'!$F$3:$F$5000,"*green return*") -> 0 | AB6: =SUMIFS('Raw Data'!$E$3:$E$5000,'Raw Data'!$P$3:$P$5000,"W9",'Raw Data'!$F$3:$F$5000,"*green return*") -> 0 | AC6: =SUMIFS('Raw Data'!$M$3:$M$5000,'Raw Data'!$P$3:$P$5000,"W10",'Raw Data'!$F$3:$F$5000,"*green return*") -> 87.32 | AD6: =SUMIFS('Raw Data'!$N$3:$N$5000,'Raw Data'!$P$3:$P$5000,"W10",'Raw Data'!$F$3:$F$5000,"*green return*") -> 0 | AE6: =SUMIFS('Raw Data'!$E$3:$E$5000,'Raw Data'!$P$3:$P$5000,"W10",'Raw Data'!$F$3:$F$5000,"*green return*") -> 1 | AF6: =SUMIFS('Raw Data'!$M$3:$M$5000,'Raw Data'!$P$3:$P$5000,"W11",'Raw Data'!$F$3:$F$5000,"*green return*") -> 0 | AG6: =SUMIFS('Raw Data'!$N$3:$N$5000,'Raw Data'!$P$3:$P$5000,"W11",'Raw Data'!$F$3:$F$5000,"*green return*") -> 0 | AH6: =SUMIFS('Raw Data'!$E$3:$E$5000,'Raw Data'!$P$3:$P$5000,"W11",'Raw Data'!$F$3:$F$5000,"*green return*") -> 0 | AI6: =SUMIFS('Raw Data'!$M$3:$M$5000,'Raw Data'!$P$3:$P$5000,"W12",'Raw Data'!$F$3:$F$5000,"*green return*") -> 0 | AJ6: =SUMIFS('Raw Data'!$N$3:$N$5000,'Raw Data'!$P$3:$P$5000,"W12",'Raw Data'!$F$3:$F$5000,"*green return*") -> 0 | AK6: =SUMIFS('Raw Data'!$E$3:$E$5000,'Raw Data'!$P$3:$P$5000,"W12",'Raw Data'!$F$3:$F$5000,"*green return*") -> 0 | AL6: =SUMIFS('Raw Data'!$M$3:$M$5000,'Raw Data'!$P$3:$P$5000,"W13",'Raw Data'!$F$3:$F$5000,"*green return*") -> 0 | AM6: =SUMIFS('Raw Data'!$N$3:$N$5000,'Raw Data'!$P$3:$P$5000,"W13",'Raw Data'!$F$3:$F$5000,"*green return*") -> 0 | AN6: =SUMIFS('Raw Data'!$E$3:$E$5000,'Raw Data'!$P$3:$P$5000,"W13",'Raw Data'!$F$3:$F$5000,"*green return*") -> 0 | AO6: =SUMIFS('Raw Data'!$M$3:$M$5000,'Raw Data'!$P$3:$P$5000,"W14",'Raw Data'!$F$3:$F$5000,"*green return*") -> 0 | AP6: =SUMIFS('Raw Data'!$N$3:$N$5000,'Raw Data'!$P$3:$P$5000,"W14",'Raw Data'!$F$3:$F$5000,"*green return*") -> 0 | AQ6: =SUMIFS('Raw Data'!$E$3:$E$5000,'Raw Data'!$P$3:$P$5000,"W14",'Raw Data'!$F$3:$F$5000,"*green return*") -> 0 | AR6: =SUMIFS('Raw Data'!$M$3:$M$5000,'Raw Data'!$P$3:$P$5000,"W15",'Raw Data'!$F$3:$F$5000,"*green return*") -> 0 | AS6: =SUMIFS('Raw Data'!$N$3:$N$5000,'Raw Data'!$P$3:$P$5000,"W15",'Raw Data'!$F$3:$F$5000,"*green return*") -> 0 | AT6: =SUMIFS('Raw Data'!$E$3:$E$5000,'Raw Data'!$P$3:$P$5000,"W15",'Raw Data'!$F$3:$F$5000,"*green return*") -> 0 | AU6: =SUMIFS('Raw Data'!$M$3:$M$5000,'Raw Data'!$P$3:$P$5000,"W16",'Raw Data'!$F$3:$F$5000,"*green return*") -> 0 | AV6: =SUMIFS('Raw Data'!$N$3:$N$5000,'Raw Data'!$P$3:$P$5000,"W16",'Raw Data'!$F$3:$F$5000,"*green return*") -> 0 | AW6: =SUMIFS('Raw Data'!$E$3:$E$5000,'Raw Data'!$P$3:$P$5000,"W16",'Raw Data'!$F$3:$F$5000,"*green return*") -> 0 | AX6: =SUMIFS('Raw Data'!$M$3:$M$5000,'Raw Data'!$P$3:$P$5000,"W17",'Raw Data'!$F$3:$F$5000,"*green return*") -> 0 | AY6: =SUMIFS('Raw Data'!$N$3:$N$5000,'Raw Data'!$P$3:$P$5000,"W17",'Raw Data'!$F$3:$F$5000,"*green return*") -> 0 | AZ6: =SUMIFS('Raw Data'!$E$3:$E$5000,'Raw Data'!$P$3:$P$5000,"W17",'Raw Data'!$F$3:$F$5000,"*green return*") -> 0 | BA6: =SUMIFS('Raw Data'!$M$3:$M$5000,'Raw Data'!$P$3:$P$5000,"W18",'Raw Data'!$F$3:$F$5000,"*green return*") -> 0 | BB6: =SUMIFS('Raw Data'!$N$3:$N$5000,'Raw Data'!$P$3:$P$5000,"W18",'Raw Data'!$F$3:$F$5000,"*green return*") -> 0 | BC6: =SUMIFS('Raw Data'!$E$3:$E$5000,'Raw Data'!$P$3:$P$5000,"W18",'Raw Data'!$F$3:$F$5000,"*green return*") -> 0 | BD6: =SUMIFS('Raw Data'!$M$3:$M$5000,'Raw Data'!$P$3:$P$5000,"W19",'Raw Data'!$F$3:$F$5000,"*green return*") -> 0 | BE6: =SUMIFS('Raw Data'!$N$3:$N$5000,'Raw Data'!$P$3:$P$5000,"W19",'Raw Data'!$F$3:$F$5000,"*green return*") -> 0 | BF6: =SUMIFS('Raw Data'!$E$3:$E$5000,'Raw Data'!$P$3:$P$5000,"W19",'Raw Data'!$F$3:$F$5000,"*green return*") -> 0 | BG6: =SUMIFS('Raw Data'!$M$3:$M$5000,'Raw Data'!$P$3:$P$5000,"W20",'Raw Data'!$F$3:$F$5000,"*green return*") -> 0 | BH6: =SUMIFS('Raw Data'!$N$3:$N$5000,'Raw Data'!$P$3:$P$5000,"W20",'Raw Data'!$F$3:$F$5000,"*green return*") -> 0 | BI6: =SUMIFS('Raw Data'!$E$3:$E$5000,'Raw Data'!$P$3:$P$5000,"W20",'Raw Data'!$F$3:$F$5000,"*green return*") -> 0 | BJ6: =SUMIFS('Raw Data'!$M$3:$M$5000,'Raw Data'!$P$3:$P$5000,"W21",'Raw Data'!$F$3:$F$5000,"*green return*") -> 0 | BK6: =SUMIFS('Raw Data'!$N$3:$N$5000,'Raw Data'!$P$3:$P$5000,"W21",'Raw Data'!$F$3:$F$5000,"*green return*") -> 0 | BL6: =SUMIFS('Raw Data'!$E$3:$E$5000,'Raw Data'!$P$3:$P$5000,"W21",'Raw Data'!$F$3:$F$5000,"*green return*") -> 0 | BM6: =SUMIFS('Raw Data'!$M$3:$M$5000,'Raw Data'!$P$3:$P$5000,"W22",'Raw Data'!$F$3:$F$5000,"*green return*") -> 0 | BN6: =SUMIFS('Raw Data'!$N$3:$N$5000,'Raw Data'!$P$3:$P$5000,"W22",'Raw Data'!$F$3:$F$5000,"*green return*") -> 0 | BO6: =SUMIFS('Raw Data'!$E$3:$E$5000,'Raw Data'!$P$3:$P$5000,"W22",'Raw Data'!$F$3:$F$5000,"*green return*") -> 0 | BP6: =SUMIFS('Raw Data'!$M$3:$M$5000,'Raw Data'!$P$3:$P$5000,"W23",'Raw Data'!$F$3:$F$5000,"*green return*") -> 0 | BQ6: =SUMIFS('Raw Data'!$N$3:$N$5000,'Raw Data'!$P$3:$P$5000,"W23",'Raw Data'!$F$3:$F$5000,"*green return*") -> 0 | BR6: =SUMIFS('Raw Data'!$E$3:$E$5000,'Raw Data'!$P$3:$P$5000,"W23",'Raw Data'!$F$3:$F$5000,"*green return*") -> 0 | BS6: =SUMIFS('Raw Data'!$M$3:$M$5000,'Raw Data'!$P$3:$P$5000,"W24",'Raw Data'!$F$3:$F$5000,"*green return*") -> 0 | BT6: =SUMIFS('Raw Data'!$N$3:$N$5000,'Raw Data'!$P$3:$P$5000,"W24",'Raw Data'!$F$3:$F$5000,"*green return*") -> 0 | BU6: =SUMIFS('Raw Data'!$E$3:$E$5000,'Raw Data'!$P$3:$P$5000,"W24",'Raw Data'!$F$3:$F$5000,"*green return*") -> 0 | BV6: =SUMIFS('Raw Data'!$M$3:$M$5000,'Raw Data'!$P$3:$P$5000,"W25",'Raw Data'!$F$3:$F$5000,"*green return*") -> 0 | BW6: =SUMIFS('Raw Data'!$N$3:$N$5000,'Raw Data'!$P$3:$P$5000,"W25",'Raw Data'!$F$3:$F$5000,"*green return*") -> 0 | BX6: =SUMIFS('Raw Data'!$E$3:$E$5000,'Raw Data'!$P$3:$P$5000,"W25",'Raw Data'!$F$3:$F$5000,"*green return*") -> 0 | BY6: =SUMIFS('Raw Data'!$M$3:$M$5000,'Raw Data'!$P$3:$P$5000,"W26",'Raw Data'!$F$3:$F$5000,"*green return*") -> 0 | BZ6: =SUMIFS('Raw Data'!$N$3:$N$5000,'Raw Data'!$P$3:$P$5000,"W26",'Raw Data'!$F$3:$F$5000,"*green return*") -> 0 | CA6: =SUMIFS('Raw Data'!$E$3:$E$5000,'Raw Data'!$P$3:$P$5000,"W26",'Raw Data'!$F$3:$F$5000,"*green return*") -> 0 | CB6: =SUMIFS('Raw Data'!$M$3:$M$5000,'Raw Data'!$P$3:$P$5000,"W27",'Raw Data'!$F$3:$F$5000,"*green return*") -> 0 | CC6: =SUMIFS('Raw Data'!$N$3:$N$5000,'Raw Data'!$P$3:$P$5000,"W27",'Raw Data'!$F$3:$F$5000,"*green return*") -> 0 | CD6: =SUMIFS('Raw Data'!$E$3:$E$5000,'Raw Data'!$P$3:$P$5000,"W27",'Raw Data'!$F$3:$F$5000,"*green return*") -> 0 | CE6: =SUMIFS('Raw Data'!$M$3:$M$5000,'Raw Data'!$P$3:$P$5000,"W28",'Raw Data'!$F$3:$F$5000,"*green return*") -> 0 | CF6: =SUMIFS('Raw Data'!$N$3:$N$5000,'Raw Data'!$P$3:$P$5000,"W28",'Raw Data'!$F$3:$F$5000,"*green return*") -> 0 | CG6: =SUMIFS('Raw Data'!$E$3:$E$5000,'Raw Data'!$P$3:$P$5000,"W28",'Raw Data'!$F$3:$F$5000,"*green return*") -> 0 | CH6: =SUMIFS('Raw Data'!$M$3:$M$5000,'Raw Data'!$P$3:$P$5000,"W29",'Raw Data'!$F$3:$F$5000,"*green return*") -> 0 | CI6: =SUMIFS('Raw Data'!$N$3:$N$5000,'Raw Data'!$P$3:$P$5000,"W29",'Raw Data'!$F$3:$F$5000,"*green return*") -> 0 | CJ6: =SUMIFS('Raw Data'!$E$3:$E$5000,'Raw Data'!$P$3:$P$5000,"W29",'Raw Data'!$F$3:$F$5000,"*green return*") -> 0 | CK6: =SUMIFS('Raw Data'!$M$3:$M$5000,'Raw Data'!$P$3:$P$5000,"W30",'Raw Data'!$F$3:$F$5000,"*green return*") -> 0 | CL6: =SUMIFS('Raw Data'!$N$3:$N$5000,'Raw Data'!$P$3:$P$5000,"W30",'Raw Data'!$F$3:$F$5000,"*green return*") -> 0 | CM6: =SUMIFS('Raw Data'!$E$3:$E$5000,'Raw Data'!$P$3:$P$5000,"W30",'Raw Data'!$F$3:$F$5000,"*green return*") -> 0 | CN6: =SUMIFS('Raw Data'!$M$3:$M$5000,'Raw Data'!$P$3:$P$5000,"W31",'Raw Data'!$F$3:$F$5000,"*green return*") -> 0 | CO6: =SUMIFS('Raw Data'!$N$3:$N$5000,'Raw Data'!$P$3:$P$5000,"W31",'Raw Data'!$F$3:$F$5000,"*green return*") -> 0 | CP6: =SUMIFS('Raw Data'!$E$3:$E$5000,'Raw Data'!$P$3:$P$5000,"W31",'Raw Data'!$F$3:$F$5000,"*green return*") -> 0 | CQ6: =SUMIFS('Raw Data'!$M$3:$M$5000,'Raw Data'!$P$3:$P$5000,"W32",'Raw Data'!$F$3:$F$5000,"*green return*") -> 0 | CR6: =SUMIFS('Raw Data'!$N$3:$N$5000,'Raw Data'!$P$3:$P$5000,"W32",'Raw Data'!$F$3:$F$5000,"*green return*") -> 0 | CS6: =SUMIFS('Raw Data'!$E$3:$E$5000,'Raw Data'!$P$3:$P$5000,"W32",'Raw Data'!$F$3:$F$5000,"*green return*") -> 0 | CT6: =SUMIFS('Raw Data'!$M$3:$M$5000,'Raw Data'!$P$3:$P$5000,"W33",'Raw Data'!$F$3:$F$5000,"*green return*") -> 0 | CU6: =SUMIFS('Raw Data'!$N$3:$N$5000,'Raw Data'!$P$3:$P$5000,"W33",'Raw Data'!$F$3:$F$5000,"*green return*") -> 0 | CV6: =SUMIFS('Raw Data'!$E$3:$E$5000,'Raw Data'!$P$3:$P$5000,"W33",'Raw Data'!$F$3:$F$5000,"*green return*") -> 0 | CW6: =SUMIFS('Raw Data'!$M$3:$M$5000,'Raw Data'!$P$3:$P$5000,"W34",'Raw Data'!$F$3:$F$5000,"*green return*") -> 0 | CX6: =SUMIFS('Raw Data'!$N$3:$N$5000,'Raw Data'!$P$3:$P$5000,"W34",'Raw Data'!$F$3:$F$5000,"*green return*") -> 0 | CY6: =SUMIFS('Raw Data'!$E$3:$E$5000,'Raw Data'!$P$3:$P$5000,"W34",'Raw Data'!$F$3:$F$5000,"*green return*") -> 0 | CZ6: =SUMIFS('Raw Data'!$M$3:$M$5000,'Raw Data'!$P$3:$P$5000,"W35",'Raw Data'!$F$3:$F$5000,"*green return*") -> 0 | DA6: =SUMIFS('Raw Data'!$N$3:$N$5000,'Raw Data'!$P$3:$P$5000,"W35",'Raw Data'!$F$3:$F$5000,"*green return*") -> 0 | DB6: =SUMIFS('Raw Data'!$E$3:$E$5000,'Raw Data'!$P$3:$P$5000,"W35",'Raw Data'!$F$3:$F$5000,"*green return*") -> 0 | DC6: =SUMIFS('Raw Data'!$M$3:$M$5000,'Raw Data'!$P$3:$P$5000,"W36",'Raw Data'!$F$3:$F$5000,"*green return*") -> 0 | DD6: =SUMIFS('Raw Data'!$N$3:$N$5000,'Raw Data'!$P$3:$P$5000,"W36",'Raw Data'!$F$3:$F$5000,"*green return*") -> 0 | DE6: =SUMIFS('Raw Data'!$E$3:$E$5000,'Raw Data'!$P$3:$P$5000,"W36",'Raw Data'!$F$3:$F$5000,"*green return*") -> 0 | DF6: =SUMIFS('Raw Data'!$M$3:$M$5000,'Raw Data'!$P$3:$P$5000,"W37",'Raw Data'!$F$3:$F$5000,"*green return*") -> 0 | DG6: =SUMIFS('Raw Data'!$N$3:$N$5000,'Raw Data'!$P$3:$P$5000,"W37",'Raw Data'!$F$3:$F$5000,"*green return*") -> 0 | DH6: =SUMIFS('Raw Data'!$E$3:$E$5000,'Raw Data'!$P$3:$P$5000,"W37",'Raw Data'!$F$3:$F$5000,"*green return*") -> 0 | DI6: =SUMIFS('Raw Data'!$M$3:$M$5000,'Raw Data'!$P$3:$P$5000,"W38",'Raw Data'!$F$3:$F$5000,"*green return*") -> 0 | DJ6: =SUMIFS('Raw Data'!$N$3:$N$5000,'Raw Data'!$P$3:$P$5000,"W38",'Raw Data'!$F$3:$F$5000,"*green return*") -> 0 | DK6: =SUMIFS('Raw Data'!$E$3:$E$5000,'Raw Data'!$P$3:$P$5000,"W38",'Raw Data'!$F$3:$F$5000,"*green return*") -> 0 | DL6: =SUMIFS('Raw Data'!$M$3:$M$5000,'Raw Data'!$P$3:$P$5000,"W39",'Raw Data'!$F$3:$F$5000,"*green return*") -> 0 | DM6: =SUMIFS('Raw Data'!$N$3:$N$5000,'Raw Data'!$P$3:$P$5000,"W39",'Raw Data'!$F$3:$F$5000,"*green return*") -> 0 | DN6: =SUMIFS('Raw Data'!$E$3:$E$5000,'Raw Data'!$P$3:$P$5000,"W39",'Raw Data'!$F$3:$F$5000,"*green return*") -> 0 | DO6: =SUMIFS('Raw Data'!$M$3:$M$5000,'Raw Data'!$P$3:$P$5000,"W40",'Raw Data'!$F$3:$F$5000,"*green return*") -> 0 | DP6: =SUMIFS('Raw Data'!$N$3:$N$5000,'Raw Data'!$P$3:$P$5000,"W40",'Raw Data'!$F$3:$F$5000,"*green return*") -> 0 | DQ6: =SUMIFS('Raw Data'!$E$3:$E$5000,'Raw Data'!$P$3:$P$5000,"W40",'Raw Data'!$F$3:$F$5000,"*green return*") -> 0 | DR6: =SUMIFS('Raw Data'!$M$3:$M$5000,'Raw Data'!$P$3:$P$5000,"W41",'Raw Data'!$F$3:$F$5000,"*green return*") -> 0 | DS6: =SUMIFS('Raw Data'!$N$3:$N$5000,'Raw Data'!$P$3:$P$5000,"W41",'Raw Data'!$F$3:$F$5000,"*green return*") -> 0 | DT6: =SUMIFS('Raw Data'!$E$3:$E$5000,'Raw Data'!$P$3:$P$5000,"W41",'Raw Data'!$F$3:$F$5000,"*green return*") -> 0 | DU6: =SUMIFS('Raw Data'!$M$3:$M$5000,'Raw Data'!$P$3:$P$5000,"W42",'Raw Data'!$F$3:$F$5000,"*green return*") -> 0 | DV6: =SUMIFS('Raw Data'!$N$3:$N$5000,'Raw Data'!$P$3:$P$5000,"W42",'Raw Data'!$F$3:$F$5000,"*green return*") -> 0 | DW6: =SUMIFS('Raw Data'!$E$3:$E$5000,'Raw Data'!$P$3:$P$5000,"W42",'Raw Data'!$F$3:$F$5000,"*green return*") -> 0 | DX6: =SUMIFS('Raw Data'!$M$3:$M$5000,'Raw Data'!$P$3:$P$5000,"W43",'Raw Data'!$F$3:$F$5000,"*green return*") -> 0 | DY6: =SUMIFS('Raw Data'!$N$3:$N$5000,'Raw Data'!$P$3:$P$5000,"W43",'Raw Data'!$F$3:$F$5000,"*green return*") -> 0 | DZ6: =SUMIFS('Raw Data'!$E$3:$E$5000,'Raw Data'!$P$3:$P$5000,"W43",'Raw Data'!$F$3:$F$5000,"*green return*") -> 0 | EA6: =SUMIFS('Raw Data'!$M$3:$M$5000,'Raw Data'!$P$3:$P$5000,"W44",'Raw Data'!$F$3:$F$5000,"*green return*") -> 0 | EB6: =SUMIFS('Raw Data'!$N$3:$N$5000,'Raw Data'!$P$3:$P$5000,"W44",'Raw Data'!$F$3:$F$5000,"*green return*") -> 0 | EC6: =SUMIFS('Raw Data'!$E$3:$E$5000,'Raw Data'!$P$3:$P$5000,"W44",'Raw Data'!$F$3:$F$5000,"*green return*") -> 0 | ED6: =SUMIFS('Raw Data'!$M$3:$M$5000,'Raw Data'!$P$3:$P$5000,"W45",'Raw Data'!$F$3:$F$5000,"*green return*") -> 0 | EE6: =SUMIFS('Raw Data'!$N$3:$N$5000,'Raw Data'!$P$3:$P$5000,"W45",'Raw Data'!$F$3:$F$5000,"*green return*") -> 0 | EF6: =SUMIFS('Raw Data'!$E$3:$E$5000,'Raw Data'!$P$3:$P$5000,"W45",'Raw Data'!$F$3:$F$5000,"*green return*") -> 0 | EG6: =SUMIFS('Raw Data'!$M$3:$M$5000,'Raw Data'!$P$3:$P$5000,"W46",'Raw Data'!$F$3:$F$5000,"*green return*") -> 0 | EH6: =SUMIFS('Raw Data'!$N$3:$N$5000,'Raw Data'!$P$3:$P$5000,"W46",'Raw Data'!$F$3:$F$5000,"*green return*") -> 0 | EI6: =SUMIFS('Raw Data'!$E$3:$E$5000,'Raw Data'!$P$3:$P$5000,"W46",'Raw Data'!$F$3:$F$5000,"*green return*") -> 0 | EJ6: =SUMIFS('Raw Data'!$M$3:$M$5000,'Raw Data'!$P$3:$P$5000,"W47",'Raw Data'!$F$3:$F$5000,"*green return*") -> 0 | EK6: =SUMIFS('Raw Data'!$N$3:$N$5000,'Raw Data'!$P$3:$P$5000,"W47",'Raw Data'!$F$3:$F$5000,"*green return*") -> 0 | EL6: =SUMIFS('Raw Data'!$E$3:$E$5000,'Raw Data'!$P$3:$P$5000,"W47",'Raw Data'!$F$3:$F$5000,"*green return*") -> 0 | EM6: =SUMIFS('Raw Data'!$M$3:$M$5000,'Raw Data'!$P$3:$P$5000,"W48",'Raw Data'!$F$3:$F$5000,"*green return*") -> 0 | EN6: =SUMIFS('Raw Data'!$N$3:$N$5000,'Raw Data'!$P$3:$P$5000,"W48",'Raw Data'!$F$3:$F$5000,"*green return*") -> 0 | EO6: =SUMIFS('Raw Data'!$E$3:$E$5000,'Raw Data'!$P$3:$P$5000,"W48",'Raw Data'!$F$3:$F$5000,"*green return*") -> 0 | EP6: =SUMIFS('Raw Data'!$M$3:$M$5000,'Raw Data'!$P$3:$P$5000,"W49",'Raw Data'!$F$3:$F$5000,"*green return*") -> 0 | EQ6: =SUMIFS('Raw Data'!$N$3:$N$5000,'Raw Data'!$P$3:$P$5000,"W49",'Raw Data'!$F$3:$F$5000,"*green return*") -> 0 | ER6: =SUMIFS('Raw Data'!$E$3:$E$5000,'Raw Data'!$P$3:$P$5000,"W49",'Raw Data'!$F$3:$F$5000,"*green return*") -> 0 | ES6: =SUMIFS('Raw Data'!$M$3:$M$5000,'Raw Data'!$P$3:$P$5000,"W50",'Raw Data'!$F$3:$F$5000,"*green return*") -> 0 | ET6: =SUMIFS('Raw Data'!$N$3:$N$5000,'Raw Data'!$P$3:$P$5000,"W50",'Raw Data'!$F$3:$F$5000,"*green return*") -> 0 | EU6: =SUMIFS('Raw Data'!$E$3:$E$5000,'Raw Data'!$P$3:$P$5000,"W50",'Raw Data'!$F$3:$F$5000,"*green return*") -> 0 | EV6: =SUMIFS('Raw Data'!$M$3:$M$5000,'Raw Data'!$P$3:$P$5000,"W51",'Raw Data'!$F$3:$F$5000,"*green return*") -> 0 | EW6: =SUMIFS('Raw Data'!$N$3:$N$5000,'Raw Data'!$P$3:$P$5000,"W51",'Raw Data'!$F$3:$F$5000,"*green return*") -> 0 | EX6: =SUMIFS('Raw Data'!$E$3:$E$5000,'Raw Data'!$P$3:$P$5000,"W51",'Raw Data'!$F$3:$F$5000,"*green return*") -> 0 | EY6: =SUMIFS('Raw Data'!$M$3:$M$5000,'Raw Data'!$P$3:$P$5000,"W52",'Raw Data'!$F$3:$F$5000,"*green return*") -> 0 | EZ6: =SUMIFS('Raw Data'!$N$3:$N$5000,'Raw Data'!$P$3:$P$5000,"W52",'Raw Data'!$F$3:$F$5000,"*green return*") -> 0 | FA6: =SUMIFS('Raw Data'!$E$3:$E$5000,'Raw Data'!$P$3:$P$5000,"W52",'Raw Data'!$F$3:$F$5000,"*green return*") -> 0 | FB6: =B6+E6+H6+K6+N6+Q6+T6+W6+Z6+AC6+AF6+AI6+AL6+AO6+AR6+AU6+AX6+BA6+BD6+BG6+BJ6+BM6+BP6+BS6+BV6+BY6+CB6+CE6+CH6+CK6+CN6+CQ6+CT6+CW6+CZ6+DC6+DF6+DI6+DL6+DO6+DR6+DU6+DX6+EA6+ED6+EG6+EJ6+EM6+EP6+ES6+EV6+EY6 -> 87.32 | FC6: =C6+F6+I6+L6+O6+R6+U6+X6+AA6+AD6+AG6+AJ6+AM6+AP6+AS6+AV6+AY6+BB6+BE6+BH6+BK6+BN6+BQ6+BT6+BW6+BZ6+CC6+CF6+CI6+CL6+CO6+CR6+CU6+CX6+DA6+DD6+DG6+DJ6+DM6+DP6+DS6+DV6+DY6+EB6+EE6+EH6+EK6+EN6+EQ6+ET6+EW6+EZ6 -> 0 | FD6: =D6+G6+J6+M6+P6+S6+V6+Y6+AB6+AE6+AH6+AK6+AN6+AQ6+AT6+AW6+AZ6+BC6+BF6+BI6+BL6+BO6+BR6+BU6+BX6+CA6+CD6+CG6+CJ6+CM6+CP6+CS6+CV6+CY6+DB6+DE6+DH6+DK6+DN6+DQ6+DT6+DW6+DZ6+EC6+EF6+EI6+EL6+EO6+ER6+EU6+EX6+FA6 -> 1
A7: Not Received | B7: =SUMIFS('Raw Data'!$M$3:$M$5000,'Raw Data'!$P$3:$P$5000,"W1",'Raw Data'!$Q$3:$Q$5000,"Not received") -> 0 | C7: =SUMIFS('Raw Data'!$N$3:$N$5000,'Raw Data'!$P$3:$P$5000,"W1",'Raw Data'!$Q$3:$Q$5000,"Not received") -> 0 | D7: =SUMIFS('Raw Data'!$E$3:$E$5000,'Raw Data'!$P$3:$P$5000,"W1",'Raw Data'!$Q$3:$Q$5000,"Not received") -> 0 | E7: =SUMIFS('Raw Data'!$M$3:$M$5000,'Raw Data'!$P$3:$P$5000,"W2",'Raw Data'!$Q$3:$Q$5000,"Not received") -> 0 | F7: =SUMIFS('Raw Data'!$N$3:$N$5000,'Raw Data'!$P$3:$P$5000,"W2",'Raw Data'!$Q$3:$Q$5000,"Not received") -> 0 | G7: =SUMIFS('Raw Data'!$E$3:$E$5000,'Raw Data'!$P$3:$P$5000,"W2",'Raw Data'!$Q$3:$Q$5000,"Not received") -> 0 | H7: =SUMIFS('Raw Data'!$M$3:$M$5000,'Raw Data'!$P$3:$P$5000,"W3",'Raw Data'!$Q$3:$Q$5000,"Not received") -> 0 | I7: =SUMIFS('Raw Data'!$N$3:$N$5000,'Raw Data'!$P$3:$P$5000,"W3",'Raw Data'!$Q$3:$Q$5000,"Not received") -> 0 | J7: =SUMIFS('Raw Data'!$E$3:$E$5000,'Raw Data'!$P$3:$P$5000,"W3",'Raw Data'!$Q$3:$Q$5000,"Not received") -> 0 | K7: =SUMIFS('Raw Data'!$M$3:$M$5000,'Raw Data'!$P$3:$P$5000,"W4",'Raw Data'!$Q$3:$Q$5000,"Not received") -> 0 | L7: =SUMIFS('Raw Data'!$N$3:$N$5000,'Raw Data'!$P$3:$P$5000,"W4",'Raw Data'!$Q$3:$Q$5000,"Not received") -> 0 | M7: =SUMIFS('Raw Data'!$E$3:$E$5000,'Raw Data'!$P$3:$P$5000,"W4",'Raw Data'!$Q$3:$Q$5000,"Not received") -> 0 | N7: =SUMIFS('Raw Data'!$M$3:$M$5000,'Raw Data'!$P$3:$P$5000,"W5",'Raw Data'!$Q$3:$Q$5000,"Not received") -> 0 | O7: =SUMIFS('Raw Data'!$N$3:$N$5000,'Raw Data'!$P$3:$P$5000,"W5",'Raw Data'!$Q$3:$Q$5000,"Not received") -> 0 | P7: =SUMIFS('Raw Data'!$E$3:$E$5000,'Raw Data'!$P$3:$P$5000,"W5",'Raw Data'!$Q$3:$Q$5000,"Not received") -> 0 | Q7: =SUMIFS('Raw Data'!$M$3:$M$5000,'Raw Data'!$P$3:$P$5000,"W6",'Raw Data'!$Q$3:$Q$5000,"Not received") -> 0 | R7: =SUMIFS('Raw Data'!$N$3:$N$5000,'Raw Data'!$P$3:$P$5000,"W6",'Raw Data'!$Q$3:$Q$5000,"Not received") -> 0 | S7: =SUMIFS('Raw Data'!$E$3:$E$5000,'Raw Data'!$P$3:$P$5000,"W6",'Raw Data'!$Q$3:$Q$5000,"Not received") -> 0 | T7: =SUMIFS('Raw Data'!$M$3:$M$5000,'Raw Data'!$P$3:$P$5000,"W7",'Raw Data'!$Q$3:$Q$5000,"Not received") -> 0 | U7: =SUMIFS('Raw Data'!$N$3:$N$5000,'Raw Data'!$P$3:$P$5000,"W7",'Raw Data'!$Q$3:$Q$5000,"Not received") -> 0 | V7: =SUMIFS('Raw Data'!$E$3:$E$5000,'Raw Data'!$P$3:$P$5000,"W7",'Raw Data'!$Q$3:$Q$5000,"Not received") -> 0 | W7: =SUMIFS('Raw Data'!$M$3:$M$5000,'Raw Data'!$P$3:$P$5000,"W8",'Raw Data'!$Q$3:$Q$5000,"Not received") -> 0 | X7: =SUMIFS('Raw Data'!$N$3:$N$5000,'Raw Data'!$P$3:$P$5000,"W8",'Raw Data'!$Q$3:$Q$5000,"Not received") -> 0 | Y7: =SUMIFS('Raw Data'!$E$3:$E$5000,'Raw Data'!$P$3:$P$5000,"W8",'Raw Data'!$Q$3:$Q$5000,"Not received") -> 0 | Z7: =SUMIFS('Raw Data'!$M$3:$M$5000,'Raw Data'!$P$3:$P$5000,"W9",'Raw Data'!$Q$3:$Q$5000,"Not received") -> 1112 | AA7: =SUMIFS('Raw Data'!$N$3:$N$5000,'Raw Data'!$P$3:$P$5000,"W9",'Raw Data'!$Q$3:$Q$5000,"Not received") -> 2284 | AB7: =SUMIFS('Raw Data'!$E$3:$E$5000,'Raw Data'!$P$3:$P$5000,"W9",'Raw Data'!$Q$3:$Q$5000,"Not received") -> 3 | AC7: =SUMIFS('Raw Data'!$M$3:$M$5000,'Raw Data'!$P$3:$P$5000,"W10",'Raw Data'!$Q$3:$Q$5000,"Not received") -> 378.66 | AD7: =SUMIFS('Raw Data'!$N$3:$N$5000,'Raw Data'!$P$3:$P$5000,"W10",'Raw Data'!$Q$3:$Q$5000,"Not received") -> 1002.36 | AE7: =SUMIFS('Raw Data'!$E$3:$E$5000,'Raw Data'!$P$3:$P$5000,"W10",'Raw Data'!$Q$3:$Q$5000,"Not received") -> 4 | AF7: =SUMIFS('Raw Data'!$M$3:$M$5000,'Raw Data'!$P$3:$P$5000,"W11",'Raw Data'!$Q$3:$Q$5000,"Not received") -> 3618 | AG7: =SUMIFS('Raw Data'!$N$3:$N$5000,'Raw Data'!$P$3:$P$5000,"W11",'Raw Data'!$Q$3:$Q$5000,"Not received") -> 7662 | AH7: =SUMIFS('Raw Data'!$E$3:$E$5000,'Raw Data'!$P$3:$P$5000,"W11",'Raw Data'!$Q$3:$Q$5000,"Not received") -> 68 | AI7: =SUMIFS('Raw Data'!$M$3:$M$5000,'Raw Data'!$P$3:$P$5000,"W12",'Raw Data'!$Q$3:$Q$5000,"Not received") -> 0 | AJ7: =SUMIFS('Raw Data'!$N$3:$N$5000,'Raw Data'!$P$3:$P$5000,"W12",'Raw Data'!$Q$3:$Q$5000,"Not received") -> 0 | AK7: =SUMIFS('Raw Data'!$E$3:$E$5000,'Raw Data'!$P$3:$P$5000,"W12",'Raw Data'!$Q$3:$Q$5000,"Not received") -> 0 | AL7: =SUMIFS('Raw Data'!$M$3:$M$5000,'Raw Data'!$P$3:$P$5000,"W13",'Raw Data'!$Q$3:$Q$5000,"Not received") -> 0 | AM7: =SUMIFS('Raw Data'!$N$3:$N$5000,'Raw Data'!$P$3:$P$5000,"W13",'Raw Data'!$Q$3:$Q$5000,"Not received") -> 0 | AN7: =SUMIFS('Raw Data'!$E$3:$E$5000,'Raw Data'!$P$3:$P$5000,"W13",'Raw Data'!$Q$3:$Q$5000,"Not received") -> 0 | AO7: =SUMIFS('Raw Data'!$M$3:$M$5000,'Raw Data'!$P$3:$P$5000,"W14",'Raw Data'!$Q$3:$Q$5000,"Not received") -> 0 | AP7: =SUMIFS('Raw Data'!$N$3:$N$5000,'Raw Data'!$P$3:$P$5000,"W14",'Raw Data'!$Q$3:$Q$5000,"Not received") -> 0 | AQ7: =SUMIFS('Raw Data'!$E$3:$E$5000,'Raw Data'!$P$3:$P$5000,"W14",'Raw Data'!$Q$3:$Q$5000,"Not received") -> 0 | AR7: =SUMIFS('Raw Data'!$M$3:$M$5000,'Raw Data'!$P$3:$P$5000,"W15",'Raw Data'!$Q$3:$Q$5000,"Not received") -> 0 | AS7: =SUMIFS('Raw Data'!$N$3:$N$5000,'Raw Data'!$P$3:$P$5000,"W15",'Raw Data'!$Q$3:$Q$5000,"Not received") -> 0 | AT7: =SUMIFS('Raw Data'!$E$3:$E$5000,'Raw Data'!$P$3:$P$5000,"W15",'Raw Data'!$Q$3:$Q$5000,"Not received") -> 0 | AU7: =SUMIFS('Raw Data'!$M$3:$M$5000,'Raw Data'!$P$3:$P$5000,"W16",'Raw Data'!$Q$3:$Q$5000,"Not received") -> 0 | AV7: =SUMIFS('Raw Data'!$N$3:$N$5000,'Raw Data'!$P$3:$P$5000,"W16",'Raw Data'!$Q$3:$Q$5000,"Not received") -> 0 | AW7: =SUMIFS('Raw Data'!$E$3:$E$5000,'Raw Data'!$P$3:$P$5000,"W16",'Raw Data'!$Q$3:$Q$5000,"Not received") -> 0 | AX7: =SUMIFS('Raw Data'!$M$3:$M$5000,'Raw Data'!$P$3:$P$5000,"W17",'Raw Data'!$Q$3:$Q$5000,"Not received") -> 0 | AY7: =SUMIFS('Raw Data'!$N$3:$N$5000,'Raw Data'!$P$3:$P$5000,"W17",'Raw Data'!$Q$3:$Q$5000,"Not received") -> 0 | AZ7: =SUMIFS('Raw Data'!$E$3:$E$5000,'Raw Data'!$P$3:$P$5000,"W17",'Raw Data'!$Q$3:$Q$5000,"Not received") -> 0 | BA7: =SUMIFS('Raw Data'!$M$3:$M$5000,'Raw Data'!$P$3:$P$5000,"W18",'Raw Data'!$Q$3:$Q$5000,"Not received") -> 0 | BB7: =SUMIFS('Raw Data'!$N$3:$N$5000,'Raw Data'!$P$3:$P$5000,"W18",'Raw Data'!$Q$3:$Q$5000,"Not received") -> 0 | BC7: =SUMIFS('Raw Data'!$E$3:$E$5000,'Raw Data'!$P$3:$P$5000,"W18",'Raw Data'!$Q$3:$Q$5000,"Not received") -> 0 | BD7: =SUMIFS('Raw Data'!$M$3:$M$5000,'Raw Data'!$P$3:$P$5000,"W19",'Raw Data'!$Q$3:$Q$5000,"Not received") -> 0 | BE7: =SUMIFS('Raw Data'!$N$3:$N$5000,'Raw Data'!$P$3:$P$5000,"W19",'Raw Data'!$Q$3:$Q$5000,"Not received") -> 0 | BF7: =SUMIFS('Raw Data'!$E$3:$E$5000,'Raw Data'!$P$3:$P$5000,"W19",'Raw Data'!$Q$3:$Q$5000,"Not received") -> 0 | BG7: =SUMIFS('Raw Data'!$M$3:$M$5000,'Raw Data'!$P$3:$P$5000,"W20",'Raw Data'!$Q$3:$Q$5000,"Not received") -> 0 | BH7: =SUMIFS('Raw Data'!$N$3:$N$5000,'Raw Data'!$P$3:$P$5000,"W20",'Raw Data'!$Q$3:$Q$5000,"Not received") -> 0 | BI7: =SUMIFS('Raw Data'!$E$3:$E$5000,'Raw Data'!$P$3:$P$5000,"W20",'Raw Data'!$Q$3:$Q$5000,"Not received") -> 0 | BJ7: =SUMIFS('Raw Data'!$M$3:$M$5000,'Raw Data'!$P$3:$P$5000,"W21",'Raw Data'!$Q$3:$Q$5000,"Not received") -> 0 | BK7: =SUMIFS('Raw Data'!$N$3:$N$5000,'Raw Data'!$P$3:$P$5000,"W21",'Raw Data'!$Q$3:$Q$5000,"Not received") -> 0 | BL7: =SUMIFS('Raw Data'!$E$3:$E$5000,'Raw Data'!$P$3:$P$5000,"W21",'Raw Data'!$Q$3:$Q$5000,"Not received") -> 0 | BM7: =SUMIFS('Raw Data'!$M$3:$M$5000,'Raw Data'!$P$3:$P$5000,"W22",'Raw Data'!$Q$3:$Q$5000,"Not received") -> 0 | BN7: =SUMIFS('Raw Data'!$N$3:$N$5000,'Raw Data'!$P$3:$P$5000,"W22",'Raw Data'!$Q$3:$Q$5000,"Not received") -> 0 | BO7: =SUMIFS('Raw Data'!$E$3:$E$5000,'Raw Data'!$P$3:$P$5000,"W22",'Raw Data'!$Q$3:$Q$5000,"Not received") -> 0 | BP7: =SUMIFS('Raw Data'!$M$3:$M$5000,'Raw Data'!$P$3:$P$5000,"W23",'Raw Data'!$Q$3:$Q$5000,"Not received") -> 0 | BQ7: =SUMIFS('Raw Data'!$N$3:$N$5000,'Raw Data'!$P$3:$P$5000,"W23",'Raw Data'!$Q$3:$Q$5000,"Not received") -> 0 | BR7: =SUMIFS('Raw Data'!$E$3:$E$5000,'Raw Data'!$P$3:$P$5000,"W23",'Raw Data'!$Q$3:$Q$5000,"Not received") -> 0 | BS7: =SUMIFS('Raw Data'!$M$3:$M$5000,'Raw Data'!$P$3:$P$5000,"W24",'Raw Data'!$Q$3:$Q$5000,"Not received") -> 0 | BT7: =SUMIFS('Raw Data'!$N$3:$N$5000,'Raw Data'!$P$3:$P$5000,"W24",'Raw Data'!$Q$3:$Q$5000,"Not received") -> 0 | BU7: =SUMIFS('Raw Data'!$E$3:$E$5000,'Raw Data'!$P$3:$P$5000,"W24",'Raw Data'!$Q$3:$Q$5000,"Not received") -> 0 | BV7: =SUMIFS('Raw Data'!$M$3:$M$5000,'Raw Data'!$P$3:$P$5000,"W25",'Raw Data'!$Q$3:$Q$5000,"Not received") -> 0 | BW7: =SUMIFS('Raw Data'!$N$3:$N$5000,'Raw Data'!$P$3:$P$5000,"W25",'Raw Data'!$Q$3:$Q$5000,"Not received") -> 0 | BX7: =SUMIFS('Raw Data'!$E$3:$E$5000,'Raw Data'!$P$3:$P$5000,"W25",'Raw Data'!$Q$3:$Q$5000,"Not received") -> 0 | BY7: =SUMIFS('Raw Data'!$M$3:$M$5000,'Raw Data'!$P$3:$P$5000,"W26",'Raw Data'!$Q$3:$Q$5000,"Not received") -> 0 | BZ7: =SUMIFS('Raw Data'!$N$3:$N$5000,'Raw Data'!$P$3:$P$5000,"W26",'Raw Data'!$Q$3:$Q$5000,"Not received") -> 0 | CA7: =SUMIFS('Raw Data'!$E$3:$E$5000,'Raw Data'!$P$3:$P$5000,"W26",'Raw Data'!$Q$3:$Q$5000,"Not received") -> 0 | CB7: =SUMIFS('Raw Data'!$M$3:$M$5000,'Raw Data'!$P$3:$P$5000,"W27",'Raw Data'!$Q$3:$Q$5000,"Not received") -> 0 | CC7: =SUMIFS('Raw Data'!$N$3:$N$5000,'Raw Data'!$P$3:$P$5000,"W27",'Raw Data'!$Q$3:$Q$5000,"Not received") -> 0 | CD7: =SUMIFS('Raw Data'!$E$3:$E$5000,'Raw Data'!$P$3:$P$5000,"W27",'Raw Data'!$Q$3:$Q$5000,"Not received") -> 0 | CE7: =SUMIFS('Raw Data'!$M$3:$M$5000,'Raw Data'!$P$3:$P$5000,"W28",'Raw Data'!$Q$3:$Q$5000,"Not received") -> 0 | CF7: =SUMIFS('Raw Data'!$N$3:$N$5000,'Raw Data'!$P$3:$P$5000,"W28",'Raw Data'!$Q$3:$Q$5000,"Not received") -> 0 | CG7: =SUMIFS('Raw Data'!$E$3:$E$5000,'Raw Data'!$P$3:$P$5000,"W28",'Raw Data'!$Q$3:$Q$5000,"Not received") -> 0 | CH7: =SUMIFS('Raw Data'!$M$3:$M$5000,'Raw Data'!$P$3:$P$5000,"W29",'Raw Data'!$Q$3:$Q$5000,"Not received") -> 0 | CI7: =SUMIFS('Raw Data'!$N$3:$N$5000,'Raw Data'!$P$3:$P$5000,"W29",'Raw Data'!$Q$3:$Q$5000,"Not received") -> 0 | CJ7: =SUMIFS('Raw Data'!$E$3:$E$5000,'Raw Data'!$P$3:$P$5000,"W29",'Raw Data'!$Q$3:$Q$5000,"Not received") -> 0 | CK7: =SUMIFS('Raw Data'!$M$3:$M$5000,'Raw Data'!$P$3:$P$5000,"W30",'Raw Data'!$Q$3:$Q$5000,"Not received") -> 0 | CL7: =SUMIFS('Raw Data'!$N$3:$N$5000,'Raw Data'!$P$3:$P$5000,"W30",'Raw Data'!$Q$3:$Q$5000,"Not received") -> 0 | CM7: =SUMIFS('Raw Data'!$E$3:$E$5000,'Raw Data'!$P$3:$P$5000,"W30",'Raw Data'!$Q$3:$Q$5000,"Not received") -> 0 | CN7: =SUMIFS('Raw Data'!$M$3:$M$5000,'Raw Data'!$P$3:$P$5000,"W31",'Raw Data'!$Q$3:$Q$5000,"Not received") -> 0 | CO7: =SUMIFS('Raw Data'!$N$3:$N$5000,'Raw Data'!$P$3:$P$5000,"W31",'Raw Data'!$Q$3:$Q$5000,"Not received") -> 0 | CP7: =SUMIFS('Raw Data'!$E$3:$E$5000,'Raw Data'!$P$3:$P$5000,"W31",'Raw Data'!$Q$3:$Q$5000,"Not received") -> 0 | CQ7: =SUMIFS('Raw Data'!$M$3:$M$5000,'Raw Data'!$P$3:$P$5000,"W32",'Raw Data'!$Q$3:$Q$5000,"Not received") -> 0 | CR7: =SUMIFS('Raw Data'!$N$3:$N$5000,'Raw Data'!$P$3:$P$5000,"W32",'Raw Data'!$Q$3:$Q$5000,"Not received") -> 0 | CS7: =SUMIFS('Raw Data'!$E$3:$E$5000,'Raw Data'!$P$3:$P$5000,"W32",'Raw Data'!$Q$3:$Q$5000,"Not received") -> 0 | CT7: =SUMIFS('Raw Data'!$M$3:$M$5000,'Raw Data'!$P$3:$P$5000,"W33",'Raw Data'!$Q$3:$Q$5000,"Not received") -> 0 | CU7: =SUMIFS('Raw Data'!$N$3:$N$5000,'Raw Data'!$P$3:$P$5000,"W33",'Raw Data'!$Q$3:$Q$5000,"Not received") -> 0 | CV7: =SUMIFS('Raw Data'!$E$3:$E$5000,'Raw Data'!$P$3:$P$5000,"W33",'Raw Data'!$Q$3:$Q$5000,"Not received") -> 0 | CW7: =SUMIFS('Raw Data'!$M$3:$M$5000,'Raw Data'!$P$3:$P$5000,"W34",'Raw Data'!$Q$3:$Q$5000,"Not received") -> 0 | CX7: =SUMIFS('Raw Data'!$N$3:$N$5000,'Raw Data'!$P$3:$P$5000,"W34",'Raw Data'!$Q$3:$Q$5000,"Not received") -> 0 | CY7: =SUMIFS('Raw Data'!$E$3:$E$5000,'Raw Data'!$P$3:$P$5000,"W34",'Raw Data'!$Q$3:$Q$5000,"Not received") -> 0 | CZ7: =SUMIFS('Raw Data'!$M$3:$M$5000,'Raw Data'!$P$3:$P$5000,"W35",'Raw Data'!$Q$3:$Q$5000,"Not received") -> 0 | DA7: =SUMIFS('Raw Data'!$N$3:$N$5000,'Raw Data'!$P$3:$P$5000,"W35",'Raw Data'!$Q$3:$Q$5000,"Not received") -> 0 | DB7: =SUMIFS('Raw Data'!$E$3:$E$5000,'Raw Data'!$P$3:$P$5000,"W35",'Raw Data'!$Q$3:$Q$5000,"Not received") -> 0 | DC7: =SUMIFS('Raw Data'!$M$3:$M$5000,'Raw Data'!$P$3:$P$5000,"W36",'Raw Data'!$Q$3:$Q$5000,"Not received") -> 0 | DD7: =SUMIFS('Raw Data'!$N$3:$N$5000,'Raw Data'!$P$3:$P$5000,"W36",'Raw Data'!$Q$3:$Q$5000,"Not received") -> 0 | DE7: =SUMIFS('Raw Data'!$E$3:$E$5000,'Raw Data'!$P$3:$P$5000,"W36",'Raw Data'!$Q$3:$Q$5000,"Not received") -> 0 | DF7: =SUMIFS('Raw Data'!$M$3:$M$5000,'Raw Data'!$P$3:$P$5000,"W37",'Raw Data'!$Q$3:$Q$5000,"Not received") -> 0 | DG7: =SUMIFS('Raw Data'!$N$3:$N$5000,'Raw Data'!$P$3:$P$5000,"W37",'Raw Data'!$Q$3:$Q$5000,"Not received") -> 0 | DH7: =SUMIFS('Raw Data'!$E$3:$E$5000,'Raw Data'!$P$3:$P$5000,"W37",'Raw Data'!$Q$3:$Q$5000,"Not received") -> 0 | DI7: =SUMIFS('Raw Data'!$M$3:$M$5000,'Raw Data'!$P$3:$P$5000,"W38",'Raw Data'!$Q$3:$Q$5000,"Not received") -> 0 | DJ7: =SUMIFS('Raw Data'!$N$3:$N$5000,'Raw Data'!$P$3:$P$5000,"W38",'Raw Data'!$Q$3:$Q$5000,"Not received") -> 0 | DK7: =SUMIFS('Raw Data'!$E$3:$E$5000,'Raw Data'!$P$3:$P$5000,"W38",'Raw Data'!$Q$3:$Q$5000,"Not received") -> 0 | DL7: =SUMIFS('Raw Data'!$M$3:$M$5000,'Raw Data'!$P$3:$P$5000,"W39",'Raw Data'!$Q$3:$Q$5000,"Not received") -> 0 | DM7: =SUMIFS('Raw Data'!$N$3:$N$5000,'Raw Data'!$P$3:$P$5000,"W39",'Raw Data'!$Q$3:$Q$5000,"Not received") -> 0 | DN7: =SUMIFS('Raw Data'!$E$3:$E$5000,'Raw Data'!$P$3:$P$5000,"W39",'Raw Data'!$Q$3:$Q$5000,"Not received") -> 0 | DO7: =SUMIFS('Raw Data'!$M$3:$M$5000,'Raw Data'!$P$3:$P$5000,"W40",'Raw Data'!$Q$3:$Q$5000,"Not received") -> 0 | DP7: =SUMIFS('Raw Data'!$N$3:$N$5000,'Raw Data'!$P$3:$P$5000,"W40",'Raw Data'!$Q$3:$Q$5000,"Not received") -> 0 | DQ7: =SUMIFS('Raw Data'!$E$3:$E$5000,'Raw Data'!$P$3:$P$5000,"W40",'Raw Data'!$Q$3:$Q$5000,"Not received") -> 0 | DR7: =SUMIFS('Raw Data'!$M$3:$M$5000,'Raw Data'!$P$3:$P$5000,"W41",'Raw Data'!$Q$3:$Q$5000,"Not received") -> 0 | DS7: =SUMIFS('Raw Data'!$N$3:$N$5000,'Raw Data'!$P$3:$P$5000,"W41",'Raw Data'!$Q$3:$Q$5000,"Not received") -> 0 | DT7: =SUMIFS('Raw Data'!$E$3:$E$5000,'Raw Data'!$P$3:$P$5000,"W41",'Raw Data'!$Q$3:$Q$5000,"Not received") -> 0 | DU7: =SUMIFS('Raw Data'!$M$3:$M$5000,'Raw Data'!$P$3:$P$5000,"W42",'Raw Data'!$Q$3:$Q$5000,"Not received") -> 0 | DV7: =SUMIFS('Raw Data'!$N$3:$N$5000,'Raw Data'!$P$3:$P$5000,"W42",'Raw Data'!$Q$3:$Q$5000,"Not received") -> 0 | DW7: =SUMIFS('Raw Data'!$E$3:$E$5000,'Raw Data'!$P$3:$P$5000,"W42",'Raw Data'!$Q$3:$Q$5000,"Not received") -> 0 | DX7: =SUMIFS('Raw Data'!$M$3:$M$5000,'Raw Data'!$P$3:$P$5000,"W43",'Raw Data'!$Q$3:$Q$5000,"Not received") -> 0 | DY7: =SUMIFS('Raw Data'!$N$3:$N$5000,'Raw Data'!$P$3:$P$5000,"W43",'Raw Data'!$Q$3:$Q$5000,"Not received") -> 0 | DZ7: =SUMIFS('Raw Data'!$E$3:$E$5000,'Raw Data'!$P$3:$P$5000,"W43",'Raw Data'!$Q$3:$Q$5000,"Not received") -> 0 | EA7: =SUMIFS('Raw Data'!$M$3:$M$5000,'Raw Data'!$P$3:$P$5000,"W44",'Raw Data'!$Q$3:$Q$5000,"Not received") -> 0 | EB7: =SUMIFS('Raw Data'!$N$3:$N$5000,'Raw Data'!$P$3:$P$5000,"W44",'Raw Data'!$Q$3:$Q$5000,"Not received") -> 0 | EC7: =SUMIFS('Raw Data'!$E$3:$E$5000,'Raw Data'!$P$3:$P$5000,"W44",'Raw Data'!$Q$3:$Q$5000,"Not received") -> 0 | ED7: =SUMIFS('Raw Data'!$M$3:$M$5000,'Raw Data'!$P$3:$P$5000,"W45",'Raw Data'!$Q$3:$Q$5000,"Not received") -> 0 | EE7: =SUMIFS('Raw Data'!$N$3:$N$5000,'Raw Data'!$P$3:$P$5000,"W45",'Raw Data'!$Q$3:$Q$5000,"Not received") -> 0 | EF7: =SUMIFS('Raw Data'!$E$3:$E$5000,'Raw Data'!$P$3:$P$5000,"W45",'Raw Data'!$Q$3:$Q$5000,"Not received") -> 0 | EG7: =SUMIFS('Raw Data'!$M$3:$M$5000,'Raw Data'!$P$3:$P$5000,"W46",'Raw Data'!$Q$3:$Q$5000,"Not received") -> 0 | EH7: =SUMIFS('Raw Data'!$N$3:$N$5000,'Raw Data'!$P$3:$P$5000,"W46",'Raw Data'!$Q$3:$Q$5000,"Not received") -> 0 | EI7: =SUMIFS('Raw Data'!$E$3:$E$5000,'Raw Data'!$P$3:$P$5000,"W46",'Raw Data'!$Q$3:$Q$5000,"Not received") -> 0 | EJ7: =SUMIFS('Raw Data'!$M$3:$M$5000,'Raw Data'!$P$3:$P$5000,"W47",'Raw Data'!$Q$3:$Q$5000,"Not received") -> 0 | EK7: =SUMIFS('Raw Data'!$N$3:$N$5000,'Raw Data'!$P$3:$P$5000,"W47",'Raw Data'!$Q$3:$Q$5000,"Not received") -> 0 | EL7: =SUMIFS('Raw Data'!$E$3:$E$5000,'Raw Data'!$P$3:$P$5000,"W47",'Raw Data'!$Q$3:$Q$5000,"Not received") -> 0 | EM7: =SUMIFS('Raw Data'!$M$3:$M$5000,'Raw Data'!$P$3:$P$5000,"W48",'Raw Data'!$Q$3:$Q$5000,"Not received") -> 0 | EN7: =SUMIFS('Raw Data'!$N$3:$N$5000,'Raw Data'!$P$3:$P$5000,"W48",'Raw Data'!$Q$3:$Q$5000,"Not received") -> 0 | EO7: =SUMIFS('Raw Data'!$E$3:$E$5000,'Raw Data'!$P$3:$P$5000,"W48",'Raw Data'!$Q$3:$Q$5000,"Not received") -> 0 | EP7: =SUMIFS('Raw Data'!$M$3:$M$5000,'Raw Data'!$P$3:$P$5000,"W49",'Raw Data'!$Q$3:$Q$5000,"Not received") -> 0 | EQ7: =SUMIFS('Raw Data'!$N$3:$N$5000,'Raw Data'!$P$3:$P$5000,"W49",'Raw Data'!$Q$3:$Q$5000,"Not received") -> 0 | ER7: =SUMIFS('Raw Data'!$E$3:$E$5000,'Raw Data'!$P$3:$P$5000,"W49",'Raw Data'!$Q$3:$Q$5000,"Not received") -> 0 | ES7: =SUMIFS('Raw Data'!$M$3:$M$5000,'Raw Data'!$P$3:$P$5000,"W50",'Raw Data'!$Q$3:$Q$5000,"Not received") -> 0 | ET7: =SUMIFS('Raw Data'!$N$3:$N$5000,'Raw Data'!$P$3:$P$5000,"W50",'Raw Data'!$Q$3:$Q$5000,"Not received") -> 0 | EU7: =SUMIFS('Raw Data'!$E$3:$E$5000,'Raw Data'!$P$3:$P$5000,"W50",'Raw Data'!$Q$3:$Q$5000,"Not received") -> 0 | EV7: =SUMIFS('Raw Data'!$M$3:$M$5000,'Raw Data'!$P$3:$P$5000,"W51",'Raw Data'!$Q$3:$Q$5000,"Not received") -> 0 | EW7: =SUMIFS('Raw Data'!$N$3:$N$5000,'Raw Data'!$P$3:$P$5000,"W51",'Raw Data'!$Q$3:$Q$5000,"Not received") -> 0 | EX7: =SUMIFS('Raw Data'!$E$3:$E$5000,'Raw Data'!$P$3:$P$5000,"W51",'Raw Data'!$Q$3:$Q$5000,"Not received") -> 0 | EY7: =SUMIFS('Raw Data'!$M$3:$M$5000,'Raw Data'!$P$3:$P$5000,"W52",'Raw Data'!$Q$3:$Q$5000,"Not received") -> 0 | EZ7: =SUMIFS('Raw Data'!$N$3:$N$5000,'Raw Data'!$P$3:$P$5000,"W52",'Raw Data'!$Q$3:$Q$5000,"Not received") -> 0 | FA7: =SUMIFS('Raw Data'!$E$3:$E$5000,'Raw Data'!$P$3:$P$5000,"W52",'Raw Data'!$Q$3:$Q$5000,"Not received") -> 0 | FB7: =B7+E7+H7+K7+N7+Q7+T7+W7+Z7+AC7+AF7+AI7+AL7+AO7+AR7+AU7+AX7+BA7+BD7+BG7+BJ7+BM7+BP7+BS7+BV7+BY7+CB7+CE7+CH7+CK7+CN7+CQ7+CT7+CW7+CZ7+DC7+DF7+DI7+DL7+DO7+DR7+DU7+DX7+EA7+ED7+EG7+EJ7+EM7+EP7+ES7+EV7+EY7 -> 5108.66 | FC7: =C7+F7+I7+L7+O7+R7+U7+X7+AA7+AD7+AG7+AJ7+AM7+AP7+AS7+AV7+AY7+BB7+BE7+BH7+BK7+BN7+BQ7+BT7+BW7+BZ7+CC7+CF7+CI7+CL7+CO7+CR7+CU7+CX7+DA7+DD7+DG7+DJ7+DM7+DP7+DS7+DV7+DY7+EB7+EE7+EH7+EK7+EN7+EQ7+ET7+EW7+EZ7 -> 10948.36 | FD7: =D7+G7+J7+M7+P7+S7+V7+Y7+AB7+AE7+AH7+AK7+AN7+AQ7+AT7+AW7+AZ7+BC7+BF7+BI7+BL7+BO7+BR7+BU7+BX7+CA7+CD7+CG7+CJ7+CM7+CP7+CS7+CV7+CY7+DB7+DE7+DH7+DK7+DN7+DQ7+DT7+DW7+DZ7+EC7+EF7+EI7+EL7+EO7+ER7+EU7+EX7+FA7 -> 75
